Workbook

Sheet Audit Checklist
A1: CHECKLIST AUDIT DE PROCES
A2: Aria | B2: Indoire | D2: Data auditului: | E2: 46266 | G2: Auditor: | H2: Silea O,
A3: Nr. Masina | B3: P1-B15 | D3: Schimb: | E3: 2 | G3: Sef linie / Supervizor: | H3: Popovici V,
A4: PN | B4: 31-0000-9121-02 | D4: Client: | E4: VW
A6: Nr. | B6: Categorie Audit | C6: Cerinta Audit | D6: Clasificare Risc | E6: Status (OK / NOK / N/A) | F6: Justificare N/A | G6: Observatii / Dovezi Obiective | H6: Actiune Imediata | I6: Responsabil Remediere | J6: Termen Remediere | K6: Verificare Eficacitate (Data / Rezultat)
A7: 1 | B7: 1. Curatenie si Standardizare (5S) | C7: Baza masinii sa fie curata fara span si mizerie. | D7: Minor
A8: 2 | C8: Sub masina curat sa fie fara ulei, span sau alte reziduuri tehnologice. | D8: Minor
A9: 3 | C9: Zona de lucru libera sa fie fara scule, suruburi sau materiale uitate pe masina. | D9: Minor
A10: 4 | C10: Mesele de lucru curate sa fie fara rugina, vopsea exfoliata, span sau mizerie. | D10: Major
A11: 5 | C11: Lada rosie/galbena sa fie curata, golita si cu folie. | D11: Minor
A12: 6 | C12: Lazile si Gitterbox-rile pentru piese bune sa fie curate, fara corpuri straine si etichetate corect. | D12: Major
A13: 7 | C13: Carucioare de transport sa fie curate, in stare buna, cu robinetul de scurgere inchis unde exista. | D13: Minor
A14: 8 | C14: Lere si calibre sa fie fara span si mizerie la conectori si segmenti, fara deteriorari sau vopsea, etichete si protectii intacte, TUV-ul de avizare nedeteriorat. | D14: Major
A15: 9 | C15: Magazia de tevi (loader) sa fie curata, cuiburile fara ulei sau span, profilele Bosch cu chedere montate. | D15: Major
A16: 10 | C16: Sistemele de descarcare sa nu fie deteriorate, profilele Bosch cu chedere montate, canale curate fara span sau ulei. | D16: Minor
A17: 11 | C17: Cabluri de alimentare si semnal sa fie curate si intacte, fara izolatie improvizata sau fire la vedere. | D17: Major
A18: 12 | C18: Traseele de cabluri sa fie fixate conform standardului, niciun cablu nu atarna liber. | D18: Minor
A19: 13 | C19: Cablurile de la panoul de comanda sa fie protejate de pat pt cabluri. | D19: Minor
A20: 14 | C20: Postul de lucru sa fie organizat (5S): scule, cutii si dulapuri curate, ordonate si etichetate; fara improvizatii la masini; fara smirghel, buline sau alte abrazive si textile neautorizate. | D20: Major
A21: 15 | B21: 2. Stare Tehnica, HMI si Safety (HSE) | C21: Insemnul "Caracteristica Importanta" este afisat vizibil pe masina, conform planului de control. | D21: Critic
A22: 16 | C22: Manometre intregi si functionale, cu valori in limitele din fisa de parametri sau tpm. | D22: Major
A23: 17 | C23: Butoanele de pe panou sunt etichetate vizibil, cu text clar in romana. | D23: Minor
A24: 18 | C24: Butoanele sunt intregi, niciunul spart, blocat sau deteriorat. | D24: Major
A25: 19 | C25: Semafoarele de avertizare functioneaza corect pe toate starile masinii. | D25: Major
A26: 20 | C26: Ledurile din butoane functioneaza, ca operatorul sa aiba semnal vizual. | D26: Minor
A27: 21 | C27: Safety: protectiile mecanice, barierele optice si butoanele de urgenta sunt montate, intacte si functioneaza. | D27: Critic
A28: 22 | C28: LOTO: la orice interventie se aplica blocarea, dispozitivele exista si oamenii stiu procedura. | D28: Critic
A29: 23 | C29: Echipamentul de protectie este purtat efectiv, conform cerintelor postului. | D29: Major
A30: 24 | C30: Iluminarea la posturile de verificare vizuala exista si este functional. | D30: Major
A31: 25 | C31: Acces la parametri: parole pe niveluri la PLC/HMI, programul incarcat coincide cu ordinul de productie, modificarile sunt inregistrate. | D31: Critic
A32: 26 | B32: 3. Calitate, Trasabilitate si IT | C32: Studiile de capabilitate (Cmk / Cpk / Ppk) exista si sunt valabile pentru cotele critice. | D32: Critic
A33: 27 | C33: In SAP este alocata masina corecta pentru avizarea procesului. | D33: Major
A34: 28 | C34: Numarul de desen al produsului finit din ordinul de productie este acelasi cu cel de pe desenul valabil. | D34: Critic
A35: 29 | C35: PN-ul materiei prime si numarul ordinului sunt trecute corect si se potrivesc cu materia prima aflata la post. | D35: Critic
A36: 30 | C36: Work-center-ul din ordinul de productie este corect cel pe care se lucreaza. | D36: Critic
A37: 31 | C37: Codurile lerelor, matritelor de gaurire sculelor montate pe masina sunt aceleasi cu cele trecute in ordinul de productie. | D37: Critic
A38: 32 | C38: Frecventa de verificare pe sablon/calibru este trecuta corect in ordin, la fel ca in planul de verificare, si se respecta la post. | D38: Critic
A39: 33 | C39: Piesele produse corespund ordinului deschis: reperul, lotul si cantitatea raportata coincid cu ce este in lada. | D39: Critic
A40: 34 | C40: Codurile instructiunilor de lucru si de verificare sunt trecute in ordin si actualizate la fel ca pe touchscreen. | D40: Major
A41: 35 | C41: Monitorizarea orara este completata si figureaza in ordinul de productie sau in format electronic pe thouchscreen. | D41: Major
...

Sheet Sumar Scor
A1: SUMAR AUDIT - SCOR SI CONFORMITATE
A3: REZULTAT GLOBAL
A4: Total itemi de audit | B4: =COUNTA('Audit Checklist'!$A$7:$A$62) -> 56
A5: Itemi evaluati OK | B5: =COUNTIF('Audit Checklist'!$E$7:$E$62,"OK") -> 0
A6: Itemi evaluati NOK | B6: =COUNTIF('Audit Checklist'!$E$7:$E$62,"NOK") -> 0
A7: Itemi N/A | B7: =COUNTIF('Audit Checklist'!$E$7:$E$62,"N/A") -> 0
A8: Itemi necompletati | B8: =B4-B5-B6-B7 -> 56
A9: Baza de evaluare (OK + NOK) | B9: =B5+B6 -> 0
A10: Procent de conformitate | B10: =IF(B9=0,0,B5/B9) -> 0
A11: NOK pe itemi clasificati Critic | B11: =COUNTIFS('Audit Checklist'!$D$7:$D$62,"Critic",'Audit Checklist'!$E$7:$E$62,"NOK") -> 0
A12: NOK Major / Minor | B12: =COUNTIFS('Audit Checklist'!$D$7:$D$62,"Major",'Audit Checklist'!$E$7:$E$62,"NOK")&" / "&COUNTIFS('Audit Checklist'!$D$7:$D$62,"Minor",'Audit Checklist'!$E$7:$E$62,"NOK") -> 0 / 0
A14: VERDICT AUDIT | B14: =IF(B9=0,"NEEVALUAT",IF(B11>0,"BLOCAT - NOK PE ITEM CRITIC",IF(B10>=0.95,"CONFORM",IF(B10>=0.85,"CONFORM CU OBSERVATII","NECONFORM - PLAN DE ACTIUNE OBLIGATORIU")))) -> NEEVALUAT
A17: DEFALCARE PE CATEGORII
A18: Categorie | B18: Total | C18: OK | D18: NOK | E18: N/A | F18: Necompletat | G18: % Conformitate
A19: 1. Curatenie si Standardizare (5S) | B19: =COUNTA('Audit Checklist'!$A$7:$A$20) -> 14 | C19: =COUNTIF('Audit Checklist'!$E$7:$E$20,"OK") -> 0 | D19: =COUNTIF('Audit Checklist'!$E$7:$E$20,"NOK") -> 0 | E19: =COUNTIF('Audit Checklist'!$E$7:$E$20,"N/A") -> 0 | F19: =B19-C19-D19-E19 -> 14 | G19: =IF((C19+D19)=0,0,C19/(C19+D19)) -> 0
A20: 2. Stare Tehnica, HMI si Safety (HSE) | B20: =COUNTA('Audit Checklist'!$A$21:$A$31) -> 11 | C20: =COUNTIF('Audit Checklist'!$E$21:$E$31,"OK") -> 0 | D20: =COUNTIF('Audit Checklist'!$E$21:$E$31,"NOK") -> 0 | E20: =COUNTIF('Audit Checklist'!$E$21:$E$31,"N/A") -> 0 | F20: =B20-C20-D20-E20 -> 11 | G20: =IF((C20+D20)=0,0,C20/(C20+D20)) -> 0
A21: 3. Calitate, Trasabilitate si IT | B21: =COUNTA('Audit Checklist'!$A$32:$A$62) -> 31 | C21: =COUNTIF('Audit Checklist'!$E$32:$E$62,"OK") -> 0 | D21: =COUNTIF('Audit Checklist'!$E$32:$E$62,"NOK") -> 0 | E21: =COUNTIF('Audit Checklist'!$E$32:$E$62,"N/A") -> 0 | F21: =B21-C21-D21-E21 -> 31 | G21: =IF((C21+D21)=0,0,C21/(C21+D21)) -> 0
A22: TOTAL | B22: =SUM(B19:B21) -> 56 | C22: =SUM(C19:C21) -> 0 | D22: =SUM(D19:D21) -> 0 | E22: =SUM(E19:E21) -> 0 | F22: =SUM(F19:F21) -> 56 | G22: =IF((C22+D22)=0,0,C22/(C22+D22)) -> 0
A25: REGULI DE SCORARE
A26: % Conformitate = itemi OK / (itemi OK + itemi NOK). Itemii N/A si cei necompletati sunt exclusi din baza de calcul.
A27: Prag: >= 95% CONFORM | 85-94.9% CONFORM CU OBSERVATII | < 85% NECONFORM.
A28: Orice NOK pe un item Critic conduce automat la verdict BLOCAT, indiferent de procentul global.
A29: Toate valorile se actualizeaza automat pe masura completarii foii Audit_Checklist.

Sheet Print A4
A1: CHECKLIST AUDIT DE PROCES
A2: Aria | C2: Nr. Masina | E2: PN
A4: Data auditului | C4: Schimb | E4: Auditor
A6: Client
A9: Nr. | B9: Cerinta Audit | C9: Risc | D9: OK | E9: NOK | F9: N/A | G9: Observatii / Actiune imediata
A10: 1. Curatenie si Standardizare (5S)
A11: ='Audit Checklist'!A7 -> 1 | B11: ='Audit Checklist'!C7 -> Baza masinii sa fie curata fara span si mizerie. | C11: ='Audit Checklist'!D7 -> Minor
A12: ='Audit Checklist'!A8 -> 2 | B12: ='Audit Checklist'!C8 -> Sub masina curat sa fie fara ulei, span sau alte reziduuri tehnologice. | C12: ='Audit Checklist'!D8 -> Minor
A13: ='Audit Checklist'!A9 -> 3 | B13: ='Audit Checklist'!C9 -> Zona de lucru libera sa fie fara scule, suruburi sau materiale uitate pe masina. | C13: ='Audit Checklist'!D9 -> Minor
A14: ='Audit Checklist'!A10 -> 4 | B14: ='Audit Checklist'!C10 -> Mesele de lucru curate sa fie fara rugina, vopsea exfoliata, span sau mizerie. | C14: ='Audit Checklist'!D10 -> Major
A15: ='Audit Checklist'!A11 -> 5 | B15: ='Audit Checklist'!C11 -> Lada rosie/galbena sa fie curata, golita si cu folie. | C15: ='Audit Checklist'!D11 -> Minor
A16: ='Audit Checklist'!A12 -> 6 | B16: ='Audit Checklist'!C12 -> Lazile si Gitterbox-rile pentru piese bune sa fie curate, fara corpuri straine si etichetate corect. | C16: ='Audit Checklist'!D12 -> Major
A17: ='Audit Checklist'!A13 -> 7 | B17: ='Audit Checklist'!C13 -> Carucioare de transport sa fie curate, in stare buna, cu robinetul de scurgere inchis unde exista. | C17: ='Audit Checklist'!D13 -> Minor
A18: ='Audit Checklist'!A14 -> 8 | B18: ='Audit Checklist'!C14 -> Lere si calibre sa fie fara span si mizerie la conectori si segmenti, fara deteriorari sau vopsea, etichete si protectii intacte, TUV-ul de avizare nedeteriorat. | C18: ='Audit Checklist'!D14 -> Major
A19: ='Audit Checklist'!A15 -> 9 | B19: ='Audit Checklist'!C15 -> Magazia de tevi (loader) sa fie curata, cuiburile fara ulei sau span, profilele Bosch cu chedere montate. | C19: ='Audit Checklist'!D15 -> Major
A20: ='Audit Checklist'!A16 -> 10 | B20: ='Audit Checklist'!C16 -> Sistemele de descarcare sa nu fie deteriorate, profilele Bosch cu chedere montate, canale curate fara span sau ulei. | C20: ='Audit Checklist'!D16 -> Minor
A21: ='Audit Checklist'!A17 -> 11 | B21: ='Audit Checklist'!C17 -> Cabluri de alimentare si semnal sa fie curate si intacte, fara izolatie improvizata sau fire la vedere. | C21: ='Audit Checklist'!D17 -> Major
A22: ='Audit Checklist'!A18 -> 12 | B22: ='Audit Checklist'!C18 -> Traseele de cabluri sa fie fixate conform standardului, niciun cablu nu atarna liber. | C22: ='Audit Checklist'!D18 -> Minor
... A24: ='Audit Checklist'!A20 -> 14 | B24: ='Audit Checklist'!C20 -> Postul de lucru sa fie organizat (5S): scule, cutii si dulapuri curate, ordonate si etichetate; fara improvizatii la masini; fara smirghel, buline sau alte abrazive si textile neautorizate. | C24: ='Audit Checklist'!D20 -> Major
A25: 2. Stare Tehnica, HMI si Safety (HSE)
A26: ='Audit Checklist'!A21 -> 15 | B26: ='Audit Checklist'!C21 -> Insemnul "Caracteristica Importanta" este afisat vizibil pe masina, conform planului de control. | C26: ='Audit Checklist'!D21 -> Critic
A27: ='Audit Checklist'!A22 -> 16 | B27: ='Audit Checklist'!C22 -> Manometre intregi si functionale, cu valori in limitele din fisa de parametri sau tpm. | C27: ='Audit Checklist'!D22 -> Major
A28: ='Audit Checklist'!A23 -> 17 | B28: ='Audit Checklist'!C23 -> Butoanele de pe panou sunt etichetate vizibil, cu text clar in romana. | C28: ='Audit Checklist'!D23 -> Minor
A29: ='Audit Checklist'!A24 -> 18 | B29: ='Audit Checklist'!C24 -> Butoanele sunt intregi, niciunul spart, blocat sau deteriorat. | C29: ='Audit Checklist'!D24 -> Major
A30: ='Audit Checklist'!A25 -> 19 | B30: ='Audit Checklist'!C25 -> Semafoarele de avertizare functioneaza corect pe toate starile masinii. | C30: ='Audit Checklist'!D25 -> Major
A31: ='Audit Checklist'!A26 -> 20 | B31: ='Audit Checklist'!C26 -> Ledurile din butoane functioneaza, ca operatorul sa aiba semnal vizual. | C31: ='Audit Checklist'!D26 -> Minor
A32: ='Audit Checklist'!A27 -> 21 | B32: ='Audit Checklist'!C27 -> Safety: protectiile mecanice, barierele optice si butoanele de urgenta sunt montate, intacte si functioneaza. | C32: ='Audit Checklist'!D27 -> Critic
A33: ='Audit Checklist'!A28 -> 22 | B33: ='Audit Checklist'!C28 -> LOTO: la orice interventie se aplica blocarea, dispozitivele exista si oamenii stiu procedura. | C33: ='Audit Checklist'!D28 -> Critic
A34: ='Audit Checklist'!A29 -> 23 | B34: ='Audit Checklist'!C29 -> Echipamentul de protectie este purtat efectiv, conform cerintelor postului. | C34: ='Audit Checklist'!D29 -> Major
A35: ='Audit Checklist'!A30 -> 24 | B35: ='Audit Checklist'!C30 -> Iluminarea la posturile de verificare vizuala exista si este functional. | C35: ='Audit Checklist'!D30 -> Major
A36: ='Audit Checklist'!A31 -> 25 | B36: ='Audit Checklist'!C31 -> Acces la parametri: parole pe niveluri la PLC/HMI, programul incarcat coincide cu ordinul de productie, modificarile sunt inregistrate. | C36: ='Audit Checklist'!D31 -> Critic
A37: 3. Calitate, Trasabilitate si IT
A38: ='Audit Checklist'!A32 -> 26 | B38: ='Audit Checklist'!C32 -> Studiile de capabilitate (Cmk / Cpk / Ppk) exista si sunt valabile pentru cotele critice. | C38: ='Audit Checklist'!D32 -> Critic
A39: ='Audit Checklist'!A33 -> 27 | B39: ='Audit Checklist'!C33 -> In SAP este alocata masina corecta pentru avizarea procesului. | C39: ='Audit Checklist'!D33 -> Major
A40: ='Audit Checklist'!A34 -> 28 | B40: ='Audit Checklist'!C34 -> Numarul de desen al produsului finit din ordinul de productie este acelasi cu cel de pe desenul valabil. | C40: ='Audit Checklist'!D34 -> Critic
A41: ='Audit Checklist'!A35 -> 29 | B41: ='Audit Checklist'!C35 -> PN-ul materiei prime si numarul ordinului sunt trecute corect si se potrivesc cu materia prima aflata la post. | C41: ='Audit Checklist'!D35 -> Critic
A42: ='Audit Checklist'!A36 -> 30 | B42: ='Audit Checklist'!C36 -> Work-center-ul din ordinul de productie este corect cel pe care se lucreaza. | C42: ='Audit Checklist'!D36 -> Critic
A43: ='Audit Checklist'!A37 -> 31 | B43: ='Audit Checklist'!C37 -> Codurile lerelor, matritelor de gaurire sculelor montate pe masina sunt aceleasi cu cele trecute in ordinul de productie. | C43: ='Audit Checklist'!D37 -> Critic
A44: ='Audit Checklist'!A38 -> 32 | B44: ='Audit Checklist'!C38 -> Frecventa de verificare pe sablon/calibru este trecuta corect in ordin, la fel ca in planul de verificare, si se respecta la post. | C44: ='Audit Checklist'!D38 -> Critic
A45: ='Audit Checklist'!A39 -> 33 | B45: ='Audit Checklist'!C39 -> Piesele produse corespund ordinului deschis: reperul, lotul si cantitatea raportata coincid cu ce este in lada. | C45: ='Audit Checklist'!D39 -> Critic
...
